Workbook

Sheet Valuation>

Sheet Nifty 50 Valuation
K6: Total Yield | L6: Expected Growth | M6: Risk Free Rate | N6: Equity Risk Premium
K7: 20 Years | L7: 20 Years | M7: 20 Years | N7: 20 Years
B8: Valuation of Nifty 50 | E8: =IF(OR(C11="",C12="",C13="",C14="",C14="",C15="",C15=""),"Provide correct Inputs",SUM(E18:E31)) -> 29600.817 | K8: 15 Years | L8: 15 Years | M8: 15 Years | N8: 15 Years
B9: Key Inputs | D9: Assumpstions | K9: 10 Years | L9: 10 Years | M9: 10 Years | N9: 10 Years
B10: Date | C10: =TODAY() -> 46255 | D10: =TODAY() -> 46255 | E10: =IF(OR(C11="",C12="",C13="",C14="",C14="",C15="",C15=""),"Provide correct Inputs",IF(E8>1.05*D11,"Undervalued",IF(E8<0.95*D11,"Overvalued","Fairly Valued"))) -> Undervalued | K10: 5 Years | L10: 5 Years | M10: 5 Years | N10: 5 Years
B11: Current Nifty 50 Price | C11: 23995.95 | D11: =C11 -> 23995.95 | K11: 3 Years | L11: 3 Years | M11: 3 Years | N11: 3 Years
B12: Total Yield | C12: 10 Years | D12: =VLOOKUP(C12,'Exp Divident & Buybacks'!K3:L11,2,0) -> 0.07787111 | M12: Latest | N12: Latest
B13: Expected Growth | C13: 10 Years | D13: =VLOOKUP(C13,'Nifty EPS Growth'!M2:N10,2,0) -> 0.10306556
B14: Risk Free Rate | C14: Latest | D14: =VLOOKUP(C14,'RFR Historicals'!O2:P12,2,0) -> 0.06837
B15: Equity Risk Premium | C15: Latest | D15: =VLOOKUP(C15,'ERP Historicals'!F3:G13,2,0) -> 0.0168
B16: Cost of Equity | D16: =D14+D15 -> 0.08517
B17: Year | C17: Expected Divident and Buyback | D17: Cumulative PV Factor (Risk Free Rate + Equity Risk Premium) | E17: Presented Value of Expected Dividents & Buyback
B18: 2026 | C18: =$D$11*$D$12*(1+$D$13)^(B18-($B$18-1)) -> 2061.1787 | D18: =1/((1+$D$16))^(B18-($B$18-1)) -> 0.9215146 | E18: =C18*D18 -> 1899.4062
B19: =B18+1 -> 2027 | C19: =$D$11*$D$12*(1+$D$13)^(B19-($B$18-1)) -> 2273.6152 | D19: =1/((1+$D$16))^(B19-($B$18-1)) -> 0.84918916 | E19: =C19*D19 -> 1930.7294
B20: =B19+1 -> 2028 | C20: =$D$11*$D$12*(1+$D$13)^(B20-($B$18-1)) -> 2507.9466 | D20: =1/((1+$D$16))^(B20-($B$18-1)) -> 0.78254021 | E20: =C20*D20 -> 1962.5691
B21: =B20+1 -> 2029 | C21: =$D$11*$D$12*(1+$D$13)^(B21-($B$18-1)) -> 2766.4295 | D21: =1/((1+$D$16))^(B21-($B$18-1)) -> 0.72112223 | E21: =C21*D21 -> 1994.9338
B22: =B21+1 -> 2030 | C22: =$D$11*$D$12*(1+$D$13)^(B22-($B$18-1)) -> 3051.5531 | D22: =1/((1+$D$16))^(B22-($B$18-1)) -> 0.66452466 | E22: =C22*D22 -> 2027.8323
B23: =B22+1 -> 2031 | C23: =$D$11*$D$12*(1+$D$13)^(B23-($B$18-1)) -> 3366.0632 | D23: =1/((1+$D$16))^(B23-($B$18-1)) -> 0.61236918 | E23: =C23*D23 -> 2061.2734
B24: =B23+1 -> 2032 | C24: =$D$11*$D$12*(1+$D$13)^(B24-($B$18-1)) -> 3712.9884 | D24: =1/((1+$D$16))^(B24-($B$18-1)) -> 0.56430714 | E24: =C24*D24 -> 2095.2659
B25: =B24+1 -> 2033 | C25: =$D$11*$D$12*(1+$D$13)^(B25-($B$18-1)) -> 4095.6696 | D25: =1/((1+$D$16))^(B25-($B$18-1)) -> 0.52001727 | E25: =C25*D25 -> 2129.8189
B26: =B25+1 -> 2034 | C26: =$D$11*$D$12*(1+$D$13)^(B26-($B$18-1)) -> 4517.7921 | D26: =1/((1+$D$16))^(B26-($B$18-1)) -> 0.47920351 | E26: =C26*D26 -> 2164.9418
B27: =B26+1 -> 2035 | C27: =$D$11*$D$12*(1+$D$13)^(B27-($B$18-1)) -> 4983.4209 | D27: =1/((1+$D$16))^(B27-($B$18-1)) -> 0.44159303 | E27: =C27*D27 -> 2200.6439
B28: =B27+1 -> 2036 | C28: =$D$11*$D$12*(1+$D$13)^(B28-($B$18-1)) -> 5497.0399 | D28: =1/((1+$D$16))^(B28-($B$18-1)) -> 0.40693443 | E28: =C28*D28 -> 2236.9348
B29: =B28+1 -> 2037 | C29: =$D$11*$D$12*(1+$D$13)^(B29-($B$18-1)) -> 6063.5954 | D29: =1/((1+$D$16))^(B29-($B$18-1)) -> 0.37499601 | E29: =C29*D29 -> 2273.8241
B30: =B29+1 -> 2038 | C30: =$D$11*$D$12*(1+$D$13)^(B30-($B$18-1)) -> 6688.5433 | D30: =1/((1+$D$16))^(B30-($B$18-1)) -> 0.3455643 | E30: =C30*D30 -> 2311.3218
B31: =B30&"-"&"∞" -> 2038-∞ | C31: =C30*(1+D13)/D15 -> 439160.82 | D31: =D30 -> 0.3455643 | E31: =E30 -> 2311.3218

Sheet Data>

Sheet Exp Divident & Buybacks
B3: Year | C3: Nifty Average Range | D3: Divident Yield | E3: Divident Amount | F3: BB Amount | G3: Total Earnings | H3: Nifty Total Earning Yield | J3: Average Nifty Earnings Yield- | K3: 20 Years | L3: =AVERAGE(H11:H30) -> 0.083741608
B4: 2000 | C4: 1376.7955 | D4: 0.012824638 | E4: =C4/D4 -> 107355.5 | F4: =E4*'BB Data'!$J$6 -> 15566.7 | G4: =E4+F4 -> 122922.2 | H4: =(G4/C4)/1000 -> 0.089281385
B5: 2001 | C5: 1117.575 | D5: 0.013090763 | E5: =C5/D5 -> 85371.265 | F5: =E5*'BB Data'!$J$6 -> 12378.954 | G5: =E5+F5 -> 97750.219 | H5: =(G5/C5)/1000 -> 0.087466362 | J5: Average Nifty Earnings Yield- | K5: 15 Years | L5: =AVERAGE(H16:H30) -> 0.081397775
B6: 2002 | C6: 1045.4833 | D6: 0.012305221 | E6: =C6/D6 -> 84962.582 | F6: =E6*'BB Data'!$J$6 -> 12319.694 | G6: =E6+F6 -> 97282.276 | H6: =(G6/C6)/1000 -> 0.09305005
B7: 2003 | C7: 1264.0708 | D7: 0.013770732 | E7: =C7/D7 -> 91794.021 | F7: =E7*'BB Data'!$J$6 -> 13310.263 | G7: =E7+F7 -> 105104.28 | H7: =(G7/C7)/1000 -> 0.083147464 | J7: Average Nifty Earnings Yield- | K7: 10 Years | L7: =AVERAGE(H21:H30) -> 0.07787111
B8: 2004 | C8: 1750.25 | D8: 0.012904032 | E8: =C8/D8 -> 135635.9 | F8: =E8*'BB Data'!$J$6 -> 19667.397 | G8: =E8+F8 -> 155303.29 | H8: =(G8/C8)/1000 -> 0.088732064
B9: 2005 | C9: 2297.1042 | D9: 0.011003629 | E9: =C9/D9 -> 208758.78 | F9: =E9*'BB Data'!$J$6 -> 30270.318 | G9: =E9+F9 -> 239029.1 | H9: =(G9/C9)/1000 -> 0.10405671 | J9: Average Nifty Earnings Yield- | K9: 5 Years | L9: =AVERAGE(H26:H30) -> 0.071779615
B10: 2006 | C10: 3420.475 | D10: 0.014283333 | E10: =C10/D10 -> 239473.16 | F10: =E10*'BB Data'!$J$6 -> 34723.947 | G10: =E10+F10 -> 274197.11 | H10: =(G10/C10)/1000 -> 0.08016346
B11: 2007 | C11: 4680.6458 | D11: 0.012505306 | E11: =C11/D11 -> 374292.78 | F11: =E11*'BB Data'!$J$6 -> 54272.983 | G11: =E11+F11 -> 428565.77 | H11: =(G11/C11)/1000 -> 0.091561246 | J11: Average Nifty Earnings Yield- | K11: 3 Years | L11: =AVERAGE(H28:H30) -> 0.084520733
B12: 2008 | C12: 4198.8333 | D12: 0.011988618 | E12: =C12/D12 -> 350234.98 | F12: =E12*'BB Data'!$J$6 -> 50784.567 | G12: =E12+F12 -> 401019.55 | H12: =(G12/C12)/1000 -> 0.095507374
B13: 2009 | C13: 4183.4458 | D13: 0.011388306 | E13: =C13/D13 -> 367345.74 | F13: =E13*'BB Data'!$J$6 -> 53265.651 | G13: =E13+F13 -> 420611.39 | H13: =(G13/C13)/1000 -> 0.10054185
B14: 2010 | C14: 5462.0917 | D14: 0.013703239 | E14: =C14/D14 -> 398598.59 | F14: =E14*'BB Data'!$J$6 -> 57797.359 | G14: =E14+F14 -> 456395.95 | H14: =(G14/C14)/1000 -> 0.083556992
B15: 2011 | C15: 5319.9292 | D15: 0.013845565 | E15: =C15/D15 -> 384233.46 | F15: =E15*'BB Data'!$J$6 -> 55714.395 | G15: =E15+F15 -> 439947.86 | H15: =(G15/C15)/1000 -> 0.082698066
B16: 2012 | C16: 5410.5625 | D16: 0.013502459 | E16: =C16/D16 -> 400709.42 | F16: =E16*'BB Data'!$J$6 -> 58103.432 | G16: =E16+F16 -> 458812.85 | H16: =(G16/C16)/1000 -> 0.084799473
B17: 2013 | C17: 5908.0875 | D17: 0.0144792 | E17: =C17/D17 -> 408039.64 | F17: =E17*'BB Data'!$J$6 -> 59166.324 | G17: =E17+F17 -> 467205.96 | H17: =(G17/C17)/1000 -> 0.079079052
B18: 2014 | C18: 7453.4958 | D18: 0.015058964 | E18: =C18/D18 -> 494954.09 | F18: =E18*'BB Data'!$J$6 -> 71769.042 | G18: =E18+F18 -> 566723.13 | H18: =(G18/C18)/1000 -> 0.07603454
B19: 2015 | C19: 8298.8208 | D19: 0.013097976 | E19: =C19/D19 -> 633595.68 | F19: =E19*'BB Data'!$J$6 -> 91872.269 | G19: =E19+F19 -> 725467.95 | H19: =(G19/C19)/1000 -> 0.087418196
B20: 2016 | C20: 8138.2083 | D20: 0.0099630952 | E20: =C20/D20 -> 816835.34 | F20: =E20*'BB Data'!$J$6 -> 118442.28 | G20: =E20+F20 -> 935277.62 | H20: =(G20/C20)/1000 -> 0.11492427
B21: 2017 | C21: 9661.4167 | D21: 0.013697942 | E21: =C21/D21 -> 705318.83 | F21: =E21*'BB Data'!$J$6 -> 102272.23 | G21: =E21+F21 -> 807591.05 | H21: =(G21/C21)/1000 -> 0.0835893
B22: 2018 | C22: 10826.45 | D22: 0.013157724 | E22: =C22/D22 -> 822820.9 | F22: =E22*'BB Data'!$J$6 -> 119310.19 | G22: =E22+F22 -> 942131.1 | H22: =(G22/C22)/1000 -> 0.087021239
B23: 2019 | C23: 11535.4 | D23: 0.010953815 | E23: =C23/D23 -> 1053094.3 | F23: =E23*'BB Data'!$J$6 -> 152700.16 | G23: =E23+F23 -> 1205794.4 | H23: =(G23/C23)/1000 -> 0.10452992
... B30: 2026 | C30: 24015.907 | D30: 0.012322 | E30: =C30/D30 -> 1949026.7 | F30: =E30*'BB Data'!$J$6 -> 282611.63 | G30: =E30+F30 -> 2231638.3 | H30: =(G30/C30)/1000 -> 0.092923341

Sheet Nifty EPS Growth
B2: Year | C2: Nifty Average Range | D2: PE Ratio | E2: Nifty EPS | F2: EPS CAGR 3 Years | G2: EPS CAGR 5 Years | H2: EPS CAGR 10 Years | I2: EPS CAGR 15 Years | J2: EPS CAGR 20 Years | L2: Average EPS CAGR- | M2: 20 Years | N2: =AVERAGE(J23:J29) -> 0.1115221
B3: 2000 | C3: 1376.7955 | D3: 22.14376 | E3: =C3/D3 -> 62.175324 | F3: - | G3: - | H3: - | I3: - | J3: -
B4: 2001 | C4: 1117.575 | D4: 16.337258 | E4: =C4/D4 -> 68.406522 | F4: - | G4: - | H4: - | I4: - | J4: - | L4: Average EPS CAGR- | M4: 15 Years | N4: =AVERAGE(I18:I29) -> 0.1013621
B5: 2002 | C5: 1045.4833 | D5: 16.087291 | E5: =C5/D5 -> 64.988154 | F5: - | G5: - | H5: - | I5: - | J5: -
B6: 2003 | C6: 1264.0708 | D6: 14.518307 | E6: =C6/D6 -> 87.067371 | F6: =_xlfn.RRI(3,E3,E6) -> 0.11878283 | G6: - | H6: - | I6: - | J6: - | L6: Average EPS CAGR- | M6: 10 Years | N6: =AVERAGE(H13:H29) -> 0.10306556
B7: 2004 | C7: 1750.25 | D7: 16.302835 | E7: =C7/D7 -> 107.35863 | F7: =_xlfn.RRI(3,E4,E7) -> 0.16210798 | G7: - | H7: - | I7: - | J7: -
B8: 2005 | C8: 2297.1042 | D8: 14.808327 | E8: =C8/D8 -> 155.12247 | F8: =_xlfn.RRI(3,E5,E8) -> 0.3364319 | G8: =_xlfn.RRI(5,E3,E8) -> 0.20063591 | H8: - | I8: - | J8: - | L8: Average EPS CAGR- | M8: 5 Years | N8: =AVERAGE(G8:G29) -> 0.12574884
B9: 2006 | C9: 3420.475 | D9: 19.17484 | E9: =C9/D9 -> 178.3835 | F9: =_xlfn.RRI(3,E6,E9) -> 0.27008586 | G9: =_xlfn.RRI(5,E4,E9) -> 0.21129921 | H9: - | I9: - | J9: -
B10: 2007 | C10: 4680.6458 | D10: 21.337711 | E10: =C10/D10 -> 219.36026 | F10: =_xlfn.RRI(3,E7,E10) -> 0.26893779 | G10: =_xlfn.RRI(5,E5,E10) -> 0.27545386 | H10: - | I10: - | J10: - | L10: Average EPS CAGR- | M10: 3 Years | N10: =AVERAGE(F6:F29) -> 0.12897747
B11: 2008 | C11: 4198.8333 | D11: 18.67 | E11: =C11/D11 -> 224.89734 | F11: =_xlfn.RRI(3,E8,E11) -> 0.13180048 | G11: =_xlfn.RRI(5,E6,E11) -> 0.20899854 | H11: - | I11: - | J11: -
B12: 2009 | C12: 4183.4458 | D12: 18.711687 | E12: =C12/D12 -> 223.57395 | F12: =_xlfn.RRI(3,E9,E12) -> 0.078173971 | G12: =_xlfn.RRI(5,E7,E12) -> 0.1580221 | H12: - | I12: - | J12: -
B13: 2010 | C13: 5462.0917 | D13: 22.889246 | E13: =C13/D13 -> 238.63135 | F13: =_xlfn.RRI(3,E10,E13) -> 0.028465783 | G13: =_xlfn.RRI(5,E8,E13) -> 0.089959997 | H13: =_xlfn.RRI(10,E3,E13) -> 0.14396028 | I13: - | J13: -
B14: 2011 | C14: 5319.9292 | D14: 19.797045 | E14: =C14/D14 -> 268.7234 | F14: =_xlfn.RRI(3,E11,E14) -> 0.061142536 | G14: =_xlfn.RRI(5,E9,E14) -> 0.085400866 | H14: =_xlfn.RRI(10,E4,E14) -> 0.14662339 | I14: - | J14: -
B15: 2012 | C15: 5410.5625 | D15: 18.056892 | E15: =C15/D15 -> 299.63974 | F15: =_xlfn.RRI(3,E12,E15) -> 0.10253589 | G15: =_xlfn.RRI(5,E10,E15) -> 0.064359376 | H15: =_xlfn.RRI(10,E5,E15) -> 0.16513573 | I15: - | J15: -
B16: 2013 | C16: 5908.0875 | D16: 17.76872 | E16: =C16/D16 -> 332.49933 | F16: =_xlfn.RRI(3,E13,E16) -> 0.11691749 | G16: =_xlfn.RRI(5,E11,E16) -> 0.081337567 | H16: =_xlfn.RRI(10,E6,E16) -> 0.14338775 | I16: - | J16: -
B17: 2014 | C17: 7453.4958 | D17: 19.901844 | E17: =C17/D17 -> 374.51282 | F17: =_xlfn.RRI(3,E14,E17) -> 0.11700144 | G17: =_xlfn.RRI(5,E12,E17) -> 0.10868736 | H17: =_xlfn.RRI(10,E7,E17) -> 0.13308626 | I17: - | J17: -
B18: 2015 | C18: 8298.8208 | D18: 22.434677 | E18: =C18/D18 -> 369.91041 | F18: =_xlfn.RRI(3,E15,E18) -> 0.072751303 | G18: =_xlfn.RRI(5,E13,E18) -> 0.091625853 | H18: =_xlfn.RRI(10,E8,E18) -> 0.090792607 | I18: =_xlfn.RRI(15,E3,E18) -> 0.12624247 | J18: -
B19: 2016 | C19: 8138.2083 | D19: 21.940324 | E19: =C19/D19 -> 370.92471 | F19: =_xlfn.RRI(3,E16,E19) -> 0.037126341 | G19: =_xlfn.RRI(5,E14,E19) -> 0.066586435 | H19: =_xlfn.RRI(10,E9,E19) -> 0.075952527 | I19: =_xlfn.RRI(15,E4,E19) -> 0.1192984 | J19: -
B20: 2017 | C20: 9661.4167 | D20: 24.728266 | E20: =C20/D20 -> 390.70336 | F20: =_xlfn.RRI(3,E17,E20) -> 0.014207503 | G20: =_xlfn.RRI(5,E15,E20) -> 0.054507196 | H20: =_xlfn.RRI(10,E10,E20) -> 0.059421834 | I20: =_xlfn.RRI(15,E5,E20) -> 0.12702668 | J20: -
B21: 2018 | C21: 10826.45 | D21: 26.411951 | E21: =C21/D21 -> 409.90724 | F21: =_xlfn.RRI(3,E18,E21) -> 0.034815701 | G21: =_xlfn.RRI(5,E16,E21) -> 0.042747033 | H21: =_xlfn.RRI(10,E11,E21) -> 0.061867007 | I21: =_xlfn.RRI(15,E6,E21) -> 0.10880543 | J21: -
B22: 2019 | C22: 11535.4 | D22: 27.69298 | E22: =C22/D22 -> 416.546 | F22: =_xlfn.RRI(3,E19,E22) -> 0.039423189 | G22: =_xlfn.RRI(5,E17,E22) -> 0.021502083 | H22: =_xlfn.RRI(10,E12,E22) -> 0.064202261 | I22: =_xlfn.RRI(15,E7,E22) -> 0.094599051 | J22: -
B23: 2020 | C23: 11150.458 | D23: 28.577619 | E23: =C23/D23 -> 390.1815 | F23: =_xlfn.RRI(3,E20,E23) -> -0.0004454277 | G23: =_xlfn.RRI(5,E18,E23) -> 0.010727363 | H23: =_xlfn.RRI(10,E13,E23) -> 0.050398077 | I23: =_xlfn.RRI(15,E8,E23) -> 0.063423202 | J23: =_xlfn.RRI(20,E3,E23) -> 0.096181406
B24: 2021 | C24: 15942.679 | D24: 30.612621 | E24: =C24/D24 -> 520.78779 | F24: =_xlfn.RRI(3,E21,E24) -> 0.083074676 | G24: =_xlfn.RRI(5,E19,E24) -> 0.070224785 | H24: =_xlfn.RRI(10,E14,E24) -> 0.068404061 | I24: =_xlfn.RRI(15,E9,E24) -> 0.074039882 | J24: =_xlfn.RRI(20,E4,E24) -> 0.10682297
B25: 2022 | C25: 17329.467 | D25: 21.515726 | E25: =C25/D25 -> 805.43259 | F25: =_xlfn.RRI(3,E22,E25) -> 0.24582031 | G25: =_xlfn.RRI(5,E20,E25) -> 0.15567684 | H25: =_xlfn.RRI(10,E15,E25) -> 0.10393367 | I25: =_xlfn.RRI(15,E10,E25) -> 0.090581391 | J25: =_xlfn.RRI(20,E5,E25) -> 0.13412193
B26: 2023 | C26: 18975.362 | D26: 21.705813 | E26: =C26/D26 -> 874.20649 | F26: =_xlfn.RRI(3,E23,E26) -> 0.30852628 | G26: =_xlfn.RRI(5,E21,E26) -> 0.16355171 | H26: =_xlfn.RRI(10,E16,E26) -> 0.10149448 | I26: =_xlfn.RRI(15,E11,E26) -> 0.094734102 | J26: =_xlfn.RRI(20,E6,E26) -> 0.12224565
B27: 2024 | C27: 23596.725 | D27: 22.716145 | E27: =C27/D27 -> 1038.7645 | F27: =_xlfn.RRI(3,E24,E27) -> 0.25878658 | G27: =_xlfn.RRI(5,E22,E27) -> 0.20052395 | H27: =_xlfn.RRI(10,E17,E27) -> 0.10740133 | I27: =_xlfn.RRI(15,E12,E27) -> 0.10782984 | J27: =_xlfn.RRI(20,E7,E27) -> 0.12017018
B28: 2025 | C28: 24634.613 | D28: 21.877912 | E28: =C28/D28 -> 1126.0038 | F28: =_xlfn.RRI(3,E25,E28) -> 0.11815899 | G28: =_xlfn.RRI(5,E23,E28) -> 0.23610294 | H28: =_xlfn.RRI(10,E18,E28) -> 0.11774911 | I28: =_xlfn.RRI(15,E13,E28) -> 0.10897262 | J28: =_xlfn.RRI(20,E8,E28) -> 0.1041886
B29: 2026 | C29: 24015.907 | D29: 21.164783 | E29: =C29/D29 -> 1134.7108 | F29: =_xlfn.RRI(3,E26,E29) -> 0.090829949 | G29: =_xlfn.RRI(5,E24,E29) -> 0.16854348 | H29: =_xlfn.RRI(10,E19,E29) -> 0.11830416 | I29: =_xlfn.RRI(15,E14,E29) -> 0.10079212 | J29: =_xlfn.RRI(20,E9,E29) -> 0.096923967

Sheet Nifty Historicals
B2: Date | C2: Closing Price | D2: Change % | E2: Monthly Return | H2: Year | I2: Nifty Average Range | J2: Average Return
B3: 46029 | C3: 23869.6 | D3: 0.0002 | H3: 2000 | I3: =AVERAGEIFS($C$3:$C$320,$B$3:$B$320,">="&DATE(H3,1,1),$B$3:$B$320,"<="&DATE(H3,12,1)) -> 1376.7955 | L3: CAGR Nifty Return- | M3: 20 Years | N3: =_xlfn.RRI(20,I9,I29) -> 0.10235285
B4: 46028 | C4: 23865.75 | D4: 0.0135 | E4: =C4/C3-1 -> -0.00016129303 | H4: =H3+1 -> 2001 | I4: =AVERAGEIFS($C$3:$C$320,$B$3:$B$320,">="&DATE(H4,1,1),$B$3:$B$320,"<="&DATE(H4,12,1)) -> 1117.575 | J4: =I4/I3-1 -> -0.18827812
B5: 46027 | C5: 23547.75 | D5: -0.0187 | E5: =C5/C4-1 -> -0.013324534 | H5: =H4+1 -> 2002 | I5: =AVERAGEIFS($C$3:$C$320,$B$3:$B$320,">="&DATE(H5,1,1),$B$3:$B$320,"<="&DATE(H5,12,1)) -> 1045.4833 | J5: =I5/I4-1 -> -0.064507229 | L5: CAGR Nifty Return- | M5: 15 Years | N5: =_xlfn.RRI(15,I14,I29) -> 0.10570569
B6: 46026 | C6: 23997.55 | D6: 0.0746 | E6: =C6/C5-1 -> 0.019101613 | H6: =H5+1 -> 2003 | I6: =AVERAGEIFS($C$3:$C$320,$B$3:$B$320,">="&DATE(H6,1,1),$B$3:$B$320,"<="&DATE(H6,12,1)) -> 1264.0708 | J6: =I6/I5-1 -> 0.20907794
B7: 46025 | C7: 22331.4 | D7: -0.1131 | E7: =C7/C6-1 -> -0.069430004 | H7: =H6+1 -> 2004 | I7: =AVERAGEIFS($C$3:$C$320,$B$3:$B$320,">="&DATE(H7,1,1),$B$3:$B$320,"<="&DATE(H7,12,1)) -> 1750.25 | J7: =I7/I6-1 -> 0.38461386 | L7: CAGR Nifty Return- | M7: 10 Years | N7: =_xlfn.RRI(10,I19,I29) -> 0.11428689
B8: 46024 | C8: 25178.65 | D8: -0.0056 | E8: =C8/C7-1 -> 0.12749984 | H8: =H7+1 -> 2005 | I8: =AVERAGEIFS($C$3:$C$320,$B$3:$B$320,">="&DATE(H8,1,1),$B$3:$B$320,"<="&DATE(H8,12,1)) -> 2297.1042 | J8: =I8/I7-1 -> 0.31244346
B9: 46023 | C9: 25320.65 | D9: -0.031 | E9: =C9/C8-1 -> 0.0056396987 | H9: =H8+1 -> 2006 | I9: =AVERAGEIFS($C$3:$C$320,$B$3:$B$320,">="&DATE(H9,1,1),$B$3:$B$320,"<="&DATE(H9,12,1)) -> 3420.475 | J9: =I9/I8-1 -> 0.48903783 | L9: CAGR Nifty Return- | M9: 5 Years | N9: =_xlfn.RRI(5,I24,I29) -> 0.085394303
B10: 45669 | C10: 26129.6 | D10: -0.0028 | E10: =C10/C9-1 -> 0.031948232 | H10: =H9+1 -> 2007 | I10: =AVERAGEIFS($C$3:$C$320,$B$3:$B$320,">="&DATE(H10,1,1),$B$3:$B$320,"<="&DATE(H10,12,1)) -> 4680.6458 | J10: =I10/I9-1 -> 0.36841983
B11: 45668 | C11: 26202.95 | D11: 0.0187 | E11: =C11/C10-1 -> 0.0028071612 | H11: =H10+1 -> 2008 | I11: =AVERAGEIFS($C$3:$C$320,$B$3:$B$320,">="&DATE(H11,1,1),$B$3:$B$320,"<="&DATE(H11,12,1)) -> 4198.8333 | J11: =I11/I10-1 -> -0.10293718 | L11: CAGR Nifty Return- | M11: 3 Years | N11: =_xlfn.RRI(3,I26,I29) -> 0.08169039
B12: 45667 | C12: 25722.1 | D12: 0.0451 | E12: =C12/C11-1 -> -0.018350987 | H12: =H11+1 -> 2009 | I12: =AVERAGEIFS($C$3:$C$320,$B$3:$B$320,">="&DATE(H12,1,1),$B$3:$B$320,"<="&DATE(H12,12,1)) -> 4183.4458 | J12: =I12/I11-1 -> -0.0036647085
B13: 45666 | C13: 24611.1 | D13: 0.0075 | E13: =C13/C12-1 -> -0.04319243 | H13: =H12+1 -> 2010 | I13: =AVERAGEIFS($C$3:$C$320,$B$3:$B$320,">="&DATE(H13,1,1),$B$3:$B$320,"<="&DATE(H13,12,1)) -> 5462.0917 | J13: =I13/I12-1 -> 0.30564417
B14: 45665 | C14: 24426.85 | D14: -0.0138 | E14: =C14/C13-1 -> -0.0074864594 | H14: =H13+1 -> 2011 | I14: =AVERAGEIFS($C$3:$C$320,$B$3:$B$320,">="&DATE(H14,1,1),$B$3:$B$320,"<="&DATE(H14,12,1)) -> 5319.9292 | J14: =I14/I13-1 -> -0.026027117
B15: 45664 | C15: 24768.35 | D15: -0.0293 | E15: =C15/C14-1 -> 0.013980517 | H15: =H14+1 -> 2012 | I15: =AVERAGEIFS($C$3:$C$320,$B$3:$B$320,">="&DATE(H15,1,1),$B$3:$B$320,"<="&DATE(H15,12,1)) -> 5410.5625 | J15: =I15/I14-1 -> 0.017036568
B16: 45663 | C16: 25517.05 | D16: 0.031 | E16: =C16/C15-1 -> 0.030228094 | H16: =H15+1 -> 2013 | I16: =AVERAGEIFS($C$3:$C$320,$B$3:$B$320,">="&DATE(H16,1,1),$B$3:$B$320,"<="&DATE(H16,12,1)) -> 5908.0875 | J16: =I16/I15-1 -> 0.091954395
B17: 45662 | C17: 24750.7 | D17: 0.0171 | E17: =C17/C16-1 -> -0.03003286 | H17: =H16+1 -> 2014 | I17: =AVERAGEIFS($C$3:$C$320,$B$3:$B$320,">="&DATE(H17,1,1),$B$3:$B$320,"<="&DATE(H17,12,1)) -> 7453.4958 | J17: =I17/I16-1 -> 0.26157506
B18: 45661 | C18: 24334.2 | D18: 0.0346 | E18: =C18/C17-1 -> -0.016827807 | H18: =H17+1 -> 2015 | I18: =AVERAGEIFS($C$3:$C$320,$B$3:$B$320,">="&DATE(H18,1,1),$B$3:$B$320,"<="&DATE(H18,12,1)) -> 8298.8208 | J18: =I18/I17-1 -> 0.11341323
B19: 45660 | C19: 23519.35 | D19: 0.063 | E19: =C19/C18-1 -> -0.033485794 | H19: =H18+1 -> 2016 | I19: =AVERAGEIFS($C$3:$C$320,$B$3:$B$320,">="&DATE(H19,1,1),$B$3:$B$320,"<="&DATE(H19,12,1)) -> 8138.2083 | J19: =I19/I18-1 -> -0.019353653
B20: 45659 | C20: 22124.7 | D20: -0.0589 | E20: =C20/C19-1 -> -0.059297982 | H20: =H19+1 -> 2017 | I20: =AVERAGEIFS($C$3:$C$320,$B$3:$B$320,">="&DATE(H20,1,1),$B$3:$B$320,"<="&DATE(H20,12,1)) -> 9661.4167 | J20: =I20/I19-1 -> 0.18716753
B21: 45658 | C21: 23508.4 | D21: -0.0058 | E21: =C21/C20-1 -> 0.062540961 | H21: =H20+1 -> 2018 | I21: =AVERAGEIFS($C$3:$C$320,$B$3:$B$320,">="&DATE(H21,1,1),$B$3:$B$320,"<="&DATE(H21,12,1)) -> 10826.45 | J21: =I21/I20-1 -> 0.12058618
B22: 45303 | C22: 23644.8 | D22: -0.0202 | E22: =C22/C21-1 -> 0.0058021813 | H22: =H21+1 -> 2019 | I22: =AVERAGEIFS($C$3:$C$320,$B$3:$B$320,">="&DATE(H22,1,1),$B$3:$B$320,"<="&DATE(H22,12,1)) -> 11535.4 | J22: =I22/I21-1 -> 0.065483145
B23: 45302 | C23: 24131.1 | D23: -0.0031 | E23: =C23/C22-1 -> 0.02056689 | H23: =H22+1 -> 2020 | I23: =AVERAGEIFS($C$3:$C$320,$B$3:$B$320,">="&DATE(H23,1,1),$B$3:$B$320,"<="&DATE(H23,12,1)) -> 11150.458 | J23: =I23/I22-1 -> -0.033370465
... B29: 45296 | C29: 22530.7 | D29: -0.0033 | E29: =C29/C28-1 -> -0.061635278 | H29: =H28+1 -> 2026 | I29: =AVERAGEIFS($C$3:$C$320,$B$3:$B$320,">="&DATE(H29,1,1),$B$3:$B$320,"<="&DATE(H29,12,1)) -> 24015.907 | J29: =I29/I28-1 -> -0.025115287
B30: 45295 | C30: 22604.85 | D30: 0.0124 | E30: =C30/C29-1 -> 0.0032910651
B31: 45294 | C31: 22326.9 | D31: 0.0157 | E31: =C31/C30-1 -> -0.012296034
B32: 45293 | C32: 21982.8 | D32: 0.0118 | E32: =C32/C31-1 -> -0.015411902
B33: 45292 | C33: 21725.7 | D33: -0.0003 | E33: =C33/C32-1 -> -0.011695507
B34: 44938 | C34: 21731.4 | D34: 0.0794 | E34: =C34/C33-1 -> 0.00026236209 | H34: Source - NSE
B35: 44937 | C35: 20133.15 | D35: 0.0552 | E35: =C35/C34-1 -> -0.073545653
B36: 44936 | C36: 19079.6 | D36: -0.0284 | E36: =C36/C35-1 -> -0.052329119
B37: 44935 | C37: 19638.3 | D37: 0.02 | E37: =C37/C36-1 -> 0.029282585
B38: 44934 | C38: 19253.8 | D38: -0.0253 | E38: =C38/C37-1 -> -0.019579088
B39: 44933 | C39: 19753.8 | D39: 0.0294 | E39: =C39/C38-1 -> 0.0259689
B40: 44932 | C40: 19189.05 | D40: 0.0353 | E40: =C40/C39-1 -> -0.028589436
B41: 44931 | C41: 18534.4 | D41: 0.026 | E41: =C41/C40-1 -> -0.034115811
B42: 44930 | C42: 18065 | D42: 0.0406 | E42: =C42/C41-1 -> -0.025325881
B43: 44929 | C43: 17359.75 | D43: 0.0032 | E43: =C43/C42-1 -> -0.039039579
B44: 44928 | C44: 17303.95 | D44: -0.0203 | E44: =C44/C43-1 -> -0.003214332
B45: 44927 | C45: 17662.15 | D45: -0.0245 | E45: =C45/C44-1 -> 0.020700476
B46: 44573 | C46: 18105.3 | D46: -0.0348 | E46: =C46/C45-1 -> 0.025090377
...

Sheet ERP Historicals
B2: Year beginning | C2: ERP % in India
B3: 2000 | C3: 0.0199 | E3: Average ERP- | F3: 20 Years | G3: =AVERAGE(C10:C29) -> 0.024775
B4: 2001 | C4: 0.0208
B5: 2002 | C5: 0.0492 | E5: Average ERP- | F5: 15 Years | G5: =AVERAGE(C15:C29) -> 0.021513333
B6: 2003 | C6: 0.0731
B7: 2004 | C7: 0.0429 | E7: Average ERP- | F7: 10 Years | G7: =AVERAGE(C20:C29) -> 0.01807
B8: 2005 | C8: 0.0462
B9: 2006 | C9: 0.0349 | E9: Average ERP- | F9: 5 Years | G9: =AVERAGE(C25:C29) -> 0.01612
B10: 2007 | C10: 0.0298
B11: 2008 | C11: 0.0218 | E11: Average ERP- | F11: 3 Years | G11: =AVERAGE(C27:C29) -> 0.015933333
B12: 2009 | C12: 0.0656
B13: 2010 | C13: 0.0246 | E13: Average ERP- | F13: Latest | G13: =C29 -> 0.0168
B14: 2011 | C14: 0.031
B15: 2012 | C15: 0.0371
B16: 2013 | C16: 0.0282
B17: 2014 | C17: 0.0281
B18: 2015 | C18: 0.0228
B19: 2016 | C19: 0.0258
B20: 2017 | C20: 0.0258
B21: 2018 | C21: 0.0165
B22: 2019 | C22: 0.0199
B23: 2020 | C23: 0.0205
B24: 2021 | C24: 0.0174
B25: 2022 | C25: 0.0163
... B29: 2026 | C29: 0.0168
B32: Source - Market Premia

Sheet RFR Historicals
B2: Date | C2: Price | D2: Open | E2: High | F2: Low | G2: Change % | J2: Year | K2: 10Y Bond Average Range | N2: Average Rate- | O2: 20 Years | P2: =AVERAGE(K10:K29) -> 0.073637542
B3: 46029 | C3: 0.06768 | D3: 0.0675 | E3: 0.06833 | F3: 0.0668 | G3: 0.0022 | J3: 2000 | K3: =AVERAGEIFS($C$3:$C$321,$B$3:$B$321,">="&DATE(J3,1,1),$B$3:$B$321,"<="&DATE(J3,12,31)) -> 0.11044917
B4: 46028 | C4: 0.06753 | D4: 0.0701 | E4: 0.0702 | F4: 0.067 | G4: -0.0357 | J4: =J3+1 -> 2001 | K4: =AVERAGEIFS($C$3:$C$321,$B$3:$B$321,">="&DATE(J4,1,1),$B$3:$B$321,"<="&DATE(J4,12,31)) -> 0.093700833 | N4: Average Rate- | O4: 15 Years | P4: =AVERAGE(K15:K29) -> 0.072203111
B5: 46027 | C5: 0.07003 | D5: 0.0701 | E5: 0.0711 | F5: 0.0692 | G5: -0.0021 | J5: =J4+1 -> 2002 | K5: =AVERAGEIFS($C$3:$C$321,$B$3:$B$321,">="&DATE(J5,1,1),$B$3:$B$321,"<="&DATE(J5,12,31)) -> 0.0719525
B6: 46026 | C6: 0.07018 | D6: 0.0695 | E6: 0.0712 | F6: 0.0686 | G6: 0.0082 | J6: =J5+1 -> 2003 | K6: =AVERAGEIFS($C$3:$C$321,$B$3:$B$321,">="&DATE(J6,1,1),$B$3:$B$321,"<="&DATE(J6,12,31)) -> 0.0560475 | N6: Average Rate- | O6: 10 Years | P6: =AVERAGE(K20:K29) -> 0.068333
B7: 46025 | C7: 0.06961 | D7: 0.0667 | E7: 0.0695 | F7: 0.0663 | G7: 0.045 | J7: =J6+1 -> 2004 | K7: =AVERAGEIFS($C$3:$C$321,$B$3:$B$321,">="&DATE(J7,1,1),$B$3:$B$321,"<="&DATE(J7,12,31)) -> 0.059314167
B8: 46024 | C8: 0.06661 | D8: 0.0676 | E8: 0.0676 | F8: 0.0664 | G8: -0.0051 | J8: =J7+1 -> 2005 | K8: =AVERAGEIFS($C$3:$C$321,$B$3:$B$321,">="&DATE(J8,1,1),$B$3:$B$321,"<="&DATE(J8,12,31)) -> 0.06971 | N8: Average Rate- | O8: 5 Years | P8: =AVERAGE(K25:K29) -> 0.069396167
B9: 46023 | C9: 0.06695 | D9: 0.0657 | E9: 0.0671 | F9: 0.0657 | G9: 0.0162 | J9: =J8+1 -> 2006 | K9: =AVERAGEIFS($C$3:$C$321,$B$3:$B$321,">="&DATE(J9,1,1),$B$3:$B$321,"<="&DATE(J9,12,31)) -> 0.076628333
B10: 45669 | C10: 0.06588 | D10: 0.0657 | E10: 0.0666 | F10: 0.0649 | G10: 0.0092 | J10: =J9+1 -> 2007 | K10: =AVERAGEIFS($C$3:$C$321,$B$3:$B$321,">="&DATE(J10,1,1),$B$3:$B$321,"<="&DATE(J10,12,31)) -> 0.079529167 | N10: Average Rate- | O10: 3 Years | P10: =AVERAGE(K27:K29) -> 0.067620556
B11: 45668 | C11: 0.06528 | D11: 0.0652 | E11: 0.0655 | F11: 0.0648 | G11: -0.0002 | J11: =J10+1 -> 2008 | K11: =AVERAGEIFS($C$3:$C$321,$B$3:$B$321,">="&DATE(J11,1,1),$B$3:$B$321,"<="&DATE(J11,12,31)) -> 0.078546667
B12: 45667 | C12: 0.06529 | D12: 0.0652 | E12: 0.0657 | F12: 0.0648 | G12: -0.0064 | J12: =J11+1 -> 2009 | K12: =AVERAGEIFS($C$3:$C$321,$B$3:$B$321,">="&DATE(J12,1,1),$B$3:$B$321,"<="&DATE(J12,12,31)) -> 0.069485833 | N12: Average Rate- | O12: Latest | P12: =K29 -> 0.06837
B13: 45666 | C13: 0.06571 | D13: 0.0658 | E13: 0.0658 | F13: 0.0645 | G13: -0.0026 | J13: =J12+1 -> 2010 | K13: =AVERAGEIFS($C$3:$C$321,$B$3:$B$321,">="&DATE(J13,1,1),$B$3:$B$321,"<="&DATE(J13,12,31)) -> 0.078485
B14: 45665 | C14: 0.06588 | D14: 0.0636 | E14: 0.0661 | F14: 0.0631 | G14: 0.0332 | J14: =J13+1 -> 2011 | K14: =AVERAGEIFS($C$3:$C$321,$B$3:$B$321,">="&DATE(J14,1,1),$B$3:$B$321,"<="&DATE(J14,12,31)) -> 0.0836575
B15: 45664 | C15: 0.06376 | D15: 0.0629 | E15: 0.0637 | F15: 0.0628 | G15: 0.0095 | J15: =J14+1 -> 2012 | K15: =AVERAGEIFS($C$3:$C$321,$B$3:$B$321,">="&DATE(J15,1,1),$B$3:$B$321,"<="&DATE(J15,12,31)) -> 0.08295
B16: 45663 | C16: 0.06316 | D16: 0.0622 | E16: 0.0631 | F16: 0.0618 | G16: 0.0171 | J16: =J15+1 -> 2013 | K16: =AVERAGEIFS($C$3:$C$321,$B$3:$B$321,">="&DATE(J16,1,1),$B$3:$B$321,"<="&DATE(J16,12,31)) -> 0.081975833
B17: 45662 | C17: 0.0621 | D17: 0.0635 | E17: 0.0639 | F17: 0.0616 | G17: -0.0224 | J17: =J16+1 -> 2014 | K17: =AVERAGEIFS($C$3:$C$321,$B$3:$B$321,">="&DATE(J17,1,1),$B$3:$B$321,"<="&DATE(J17,12,31)) -> 0.085550833
B18: 45661 | C18: 0.06352 | D18: 0.0657 | E18: 0.0657 | F18: 0.0631 | G18: -0.0332 | J18: =J17+1 -> 2015 | K18: =AVERAGEIFS($C$3:$C$321,$B$3:$B$321,">="&DATE(J18,1,1),$B$3:$B$321,"<="&DATE(J18,12,31)) -> 0.077501667 | N18: 10Y Gov Bond Average Range (2000-2026)
B19: 45660 | C19: 0.0657 | D19: 0.0673 | E19: 0.0674 | F19: 0.0657 | G19: -0.0223 | J19: =J18+1 -> 2016 | K19: =AVERAGEIFS($C$3:$C$321,$B$3:$B$321,">="&DATE(J19,1,1),$B$3:$B$321,"<="&DATE(J19,12,31)) -> 0.071738333
B20: 45659 | C20: 0.0672 | D20: 0.0666 | E20: 0.0672 | F20: 0.0665 | G20: 0.0045 | J20: =J19+1 -> 2017 | K20: =AVERAGEIFS($C$3:$C$321,$B$3:$B$321,">="&DATE(J20,1,1),$B$3:$B$321,"<="&DATE(J20,12,31)) -> 0.0674725
B21: 45658 | C21: 0.0669 | D21: 0.0678 | E21: 0.0684 | F21: 0.0667 | G21: -0.0104 | J21: =J20+1 -> 2018 | K21: =AVERAGEIFS($C$3:$C$321,$B$3:$B$321,">="&DATE(J21,1,1),$B$3:$B$321,"<="&DATE(J21,12,31)) -> 0.077189167
B22: 45303 | C22: 0.0676 | D22: 0.06802 | E22: 0.06807 | F22: 0.06668 | G22: 0.0013 | J22: =J21+1 -> 2019 | K22: =AVERAGEIFS($C$3:$C$321,$B$3:$B$321,">="&DATE(J22,1,1),$B$3:$B$321,"<="&DATE(J22,12,31)) -> 0.069185
B23: 45302 | C23: 0.06751 | D23: 0.06831 | E23: 0.06863 | F23: 0.06739 | G23: -0.0132 | J23: =J22+1 -> 2020 | K23: =AVERAGEIFS($C$3:$C$321,$B$3:$B$321,">="&DATE(J23,1,1),$B$3:$B$321,"<="&DATE(J23,12,31)) -> 0.0606125
B24: 45301 | C24: 0.06841 | D24: 0.06759 | E24: 0.06875 | F24: 0.0673 | G24: 0.0135 | J24: =J23+1 -> 2021 | K24: =AVERAGEIFS($C$3:$C$321,$B$3:$B$321,">="&DATE(J24,1,1),$B$3:$B$321,"<="&DATE(J24,12,31)) -> 0.06189
B25: 45300 | C25: 0.0675 | D25: 0.06877 | E25: 0.06885 | F25: 0.06706 | G25: -0.0165 | J25: =J24+1 -> 2022 | K25: =AVERAGEIFS($C$3:$C$321,$B$3:$B$321,">="&DATE(J25,1,1),$B$3:$B$321,"<="&DATE(J25,12,31)) -> 0.0718825
B26: 45299 | C26: 0.06863 | D26: 0.06912 | E26: 0.06919 | F26: 0.06843 | G26: -0.0088 | J26: =J25+1 -> 2023 | K26: =AVERAGEIFS($C$3:$C$321,$B$3:$B$321,">="&DATE(J26,1,1),$B$3:$B$321,"<="&DATE(J26,12,31)) -> 0.072236667
B27: 45298 | C27: 0.06924 | D27: 0.07023 | E27: 0.07024 | F27: 0.0691 | G27: -0.012 | J27: =J26+1 -> 2024 | K27: =AVERAGEIFS($C$3:$C$321,$B$3:$B$321,">="&DATE(J27,1,1),$B$3:$B$321,"<="&DATE(J27,12,31)) -> 0.06946
B28: 45297 | C28: 0.07008 | D28: 0.06955 | E28: 0.07062 | F28: 0.06945 | G28: 0.0031 | J28: =J27+1 -> 2025 | K28: =AVERAGEIFS($C$3:$C$321,$B$3:$B$321,">="&DATE(J28,1,1),$B$3:$B$321,"<="&DATE(J28,12,31)) -> 0.065031667
B29: 45296 | C29: 0.06986 | D29: 0.0717 | E29: 0.07173 | F29: 0.06967 | G29: -0.029 | J29: =J28+1 -> 2026 | K29: =AVERAGEIFS($C$3:$C$321,$B$3:$B$321,">="&DATE(J29,1,1),$B$3:$B$321,"<="&DATE(J29,12,31)) -> 0.06837
B30: 45295 | C30: 0.07195 | D30: 0.07085 | E30: 0.07242 | F30: 0.07075 | G30: 0.0203
B31: 45294 | C31: 0.07052 | D31: 0.07062 | E31: 0.07103 | F31: 0.07006 | G31: -0.0037
B32: 45293 | C32: 0.07078 | D32: 0.07129 | E32: 0.0714 | F32: 0.07021 | G32: -0.0092
B33: 45292 | C33: 0.07144 | D33: 0.07207 | E33: 0.07239 | F33: 0.07134 | G33: -0.0045 | J33: Source - Investing.com
B34: 44938 | C34: 0.07176 | D34: 0.07293 | E34: 0.07298 | F34: 0.07147 | G34: -0.0142
B35: 44937 | C35: 0.07279 | D35: 0.07376 | E35: 0.07376 | F35: 0.07194 | G35: -0.0098
B36: 44936 | C36: 0.07351 | D36: 0.07239 | E36: 0.07395 | F36: 0.07205 | G36: 0.0196
B37: 44935 | C37: 0.0721 | D37: 0.07174 | E37: 0.07241 | F37: 0.07086 | G37: 0.0061
B38: 44934 | C38: 0.07166 | D38: 0.07186 | E38: 0.07256 | F38: 0.07147 | G38: -0.0008
B39: 44933 | C39: 0.07172 | D39: 0.07113 | E39: 0.07185 | F39: 0.07047 | G39: 0.0087
B40: 44932 | C40: 0.0711 | D40: 0.07019 | E40: 0.07117 | F40: 0.06963 | G40: 0.0173
B41: 44931 | C41: 0.06989 | D41: 0.07135 | E41: 0.07138 | F41: 0.06947 | G41: -0.0178
...

Sheet BB Data
B2: Industry name | C2: Number of firms | D2: Dividends | E2: Dividends + Buybacks | F2: Buyback | G2: Buyback as % Divident
B3: Advertising | C3: 52 | D3: 571.1 | E3: 2751.489 | F3: 2180.389 | G3: 0.3817876
B4: Aerospace/Defense | C4: 79 | D4: 12526.491 | E4: 32083.936 | F4: 19557.445 | G4: 0.15612868
B5: Air Transport | C5: 23 | D5: 812 | E5: 5182.741 | F5: 4370.741 | G5: 0.5382686 | I5: Mean of Buyback as % of Divident | J5: =AVERAGE(G3:G96) -> 0.25585396
B6: Apparel | C6: 35 | D6: 1218.62 | E6: 6158.236 | F6: 4939.616 | G6: 0.40534506 | I6: Trimed Mean of Buyback as a % of Divident (10%) | J6: =TRIMMEAN(G3:G96,0.5) -> 0.14500141
B7: Auto & Truck | C7: 33 | D7: 3743.2 | E7: 12518.957 | F7: 8775.757 | G7: 0.23444531
B8: Auto Parts | C8: 35 | D8: 693.93 | E8: 2351.133 | F8: 1657.203 | G8: 0.23881415
B9: Bank (Money Center) | C9: 15 | D9: 40401.779 | E9: 91770.65 | F9: 51368.871 | G9: 0.12714507
B10: Banks (Regional) | C10: 568 | D10: 18200.2 | E10: 29963.263 | F10: 11763.063 | G10: 0.064631506
B11: Beverage (Alcoholic) | C11: 14 | D11: 1538 | E11: 3718.805 | F11: 2180.805 | G11: 0.14179486
B12: Beverage (Soft) | C12: 27 | D12: 17711 | E12: 20640.19 | F12: 2929.19 | G12: 0.016538818
B13: Broadcasting | C13: 24 | D13: 894.77 | E13: 2423.978 | F13: 1529.208 | G13: 0.17090515
B14: Brokerage & Investment Banking | C14: 32 | D14: 14207.814 | E14: 31828.729 | F14: 17620.915 | G14: 0.1240227
B15: Building Materials | C15: 41 | D15: 2369.83 | E15: 12320.74 | F15: 9950.91 | G15: 0.41989974
B16: Business & Consumer Services | C16: 155 | D16: 8076.9079 | E16: 22036.405 | F16: 13959.497 | G16: 0.17283219
B17: Cable TV | C17: 9 | D17: 5224.2 | E17: 17685.43 | F17: 12461.23 | G17: 0.23852896
B18: Chemical (Basic) | C18: 29 | D18: 4092.3 | E18: 4792.71 | F18: 700.41 | G18: 0.017115314
... B96: Utility (Water) | C96: 14 | D96: 1246.75 | E96: 1253.591 | F96: 6.841 | G96: 0.00054870664
B98: Source - Damodaran Sir's Website
